Traceback (most recent call last):
  File "C:\Users\Onat\Desktop\starter_code_copy\train.py", line 307, in <module>
    losses = estimate_loss()
             ^^^^^^^^^^^^^^^
  File "C:\Users\Onat\AppData\Local\Packages\PythonSoftwareFoundation.Python.3.11_qbz5n2kfra8p0\LocalCache\local-packages\Python311\site-packages\torch\utils\_contextlib.py", line 116, in decorate_context
    return func(*args, **kwargs)
           ^^^^^^^^^^^^^^^^^^^^^
  File "C:\Users\Onat\Desktop\starter_code_copy\train.py", line 261, in estimate_loss
    logits, loss = model(X, Y)
                   ^^^^^^^^^^^
  File "C:\Users\Onat\AppData\Local\Packages\PythonSoftwareFoundation.Python.3.11_qbz5n2kfra8p0\LocalCache\local-packages\Python311\site-packages\torch\nn\modules\module.py", line 1739, in _wrapped_call_impl
    return self._call_impl(*args, **kwargs)
           ^^^^^^^^^^^^^^^^^^^^^^^^^^^^^^^^
  File "C:\Users\Onat\AppData\Local\Packages\PythonSoftwareFoundation.Python.3.11_qbz5n2kfra8p0\LocalCache\local-packages\Python311\site-packages\torch\nn\modules\module.py", line 1750, in _call_impl
    return forward_call(*args, **kwargs)
           ^^^^^^^^^^^^^^^^^^^^^^^^^^^^^
  File "C:\Users\Onat\Desktop\starter_code_copy\model.py", line 173, in forward
    assert t <= self.config.block_size, f"Cannot forward sequence of length {t}, block size is only {self.config.block_size}"
           ^^^^^^^^^^^^^^^^^^^^^^^^^^^
AssertionError: Cannot forward sequence of length 512, block size is only 256
